2025-04-28 22:14:04 - fraudDetection - DEBUG - logger.py:15 - Starting execution of train_classifier
2025-04-28 22:14:04 - fraudDetection - INFO - training_pipeline.py:27 - Starting fraud classifier training
2025-04-28 22:14:04 - fraudDetection - ERROR - logger.py:25 - Failed executing train_classifier after 0.0000 seconds: [Errno 2] No such file or directory: 'C:\\Users\\renzd\\Desktop\\fraud_detection_system\\data/raw/creditcard.csv'
2025-04-28 22:14:05 - fraudDetection - DEBUG - logger.py:26 - Traceback (most recent call last):
  File "C:\Users\renzd\Desktop\fraud_detection_system\infrastructure\utils\logger.py", line 18, in wrapper
    result = func(*args, **kwargs)
             ^^^^^^^^^^^^^^^^^^^^^
  File "C:\Users\renzd\Desktop\fraud_detection_system\training_pipeline.py", line 34, in train_classifier
    df = process_raw_data(save=True)
         ^^^^^^^^^^^^^^^^^^^^^^^^^^^
  File "C:\Users\renzd\Desktop\fraud_detection_system\infrastructure\utils\data_loader.py", line 22, in process_raw_data
    df = load_raw_data()
         ^^^^^^^^^^^^^^^
  File "C:\Users\renzd\Desktop\fraud_detection_system\infrastructure\utils\data_loader.py", line 11, in load_raw_data
    return pd.read_csv(data_path)
           ^^^^^^^^^^^^^^^^^^^^^^
  File "C:\Users\renzd\AppData\Local\Programs\Python\Python311\Lib\site-packages\pandas\io\parsers\readers.py", line 1026, in read_csv
    return _read(filepath_or_buffer, kwds)
           ^^^^^^^^^^^^^^^^^^^^^^^^^^^^^^^
  File "C:\Users\renzd\AppData\Local\Programs\Python\Python311\Lib\site-packages\pandas\io\parsers\readers.py", line 620, in _read
    parser = TextFileReader(filepath_or_buffer, **kwds)
             ^^^^^^^^^^^^^^^^^^^^^^^^^^^^^^^^^^^^^^^^^^
  File "C:\Users\renzd\AppData\Local\Programs\Python\Python311\Lib\site-packages\pandas\io\parsers\readers.py", line 1620, in __init__
    self._engine = self._make_engine(f, self.engine)
                   ^^^^^^^^^^^^^^^^^^^^^^^^^^^^^^^^^
  File "C:\Users\renzd\AppData\Local\Programs\Python\Python311\Lib\site-packages\pandas\io\parsers\readers.py", line 1880, in _make_engine
    self.handles = get_handle(
                   ^^^^^^^^^^^
  File "C:\Users\renzd\AppData\Local\Programs\Python\Python311\Lib\site-packages\pandas\io\common.py", line 873, in get_handle
    handle = open(
             ^^^^^
FileNotFoundError: [Errno 2] No such file or directory: 'C:\\Users\\renzd\\Desktop\\fraud_detection_system\\data/raw/creditcard.csv'

2025-04-28 22:15:10 - fraudDetection - DEBUG - logger.py:15 - Starting execution of train_classifier
2025-04-28 22:15:10 - fraudDetection - INFO - training_pipeline.py:27 - Starting fraud classifier training
2025-04-28 22:15:11 - fraudDetection - ERROR - logger.py:25 - Failed executing train_classifier after 1.5558 seconds: Unable to find a usable engine; tried using: 'pyarrow', 'fastparquet'.
A suitable version of pyarrow or fastparquet is required for parquet support.
Trying to import the above resulted in these errors:
 - Missing optional dependency 'pyarrow'. pyarrow is required for parquet support. Use pip or conda to install pyarrow.
 - Missing optional dependency 'fastparquet'. fastparquet is required for parquet support. Use pip or conda to install fastparquet.
2025-04-28 22:15:11 - fraudDetection - DEBUG - logger.py:26 - Traceback (most recent call last):
  File "C:\Users\renzd\Desktop\fraud_detection_system\infrastructure\utils\logger.py", line 18, in wrapper
    result = func(*args, **kwargs)
             ^^^^^^^^^^^^^^^^^^^^^
  File "C:\Users\renzd\Desktop\fraud_detection_system\training_pipeline.py", line 34, in train_classifier
    df = process_raw_data(save=True)
         ^^^^^^^^^^^^^^^^^^^^^^^^^^^
  File "C:\Users\renzd\Desktop\fraud_detection_system\infrastructure\utils\data_loader.py", line 46, in process_raw_data
    processed_df.to_parquet(output_path, index=False)
  File "C:\Users\renzd\AppData\Local\Programs\Python\Python311\Lib\site-packages\pandas\util\_decorators.py", line 333, in wrapper
    return func(*args, **kwargs)
           ^^^^^^^^^^^^^^^^^^^^^
  File "C:\Users\renzd\AppData\Local\Programs\Python\Python311\Lib\site-packages\pandas\core\frame.py", line 3113, in to_parquet
    return to_parquet(
           ^^^^^^^^^^^
  File "C:\Users\renzd\AppData\Local\Programs\Python\Python311\Lib\site-packages\pandas\io\parquet.py", line 476, in to_parquet
    impl = get_engine(engine)
           ^^^^^^^^^^^^^^^^^^
  File "C:\Users\renzd\AppData\Local\Programs\Python\Python311\Lib\site-packages\pandas\io\parquet.py", line 67, in get_engine
    raise ImportError(
ImportError: Unable to find a usable engine; tried using: 'pyarrow', 'fastparquet'.
A suitable version of pyarrow or fastparquet is required for parquet support.
Trying to import the above resulted in these errors:
 - Missing optional dependency 'pyarrow'. pyarrow is required for parquet support. Use pip or conda to install pyarrow.
 - Missing optional dependency 'fastparquet'. fastparquet is required for parquet support. Use pip or conda to install fastparquet.

2025-04-28 22:17:47 - fraudDetection - DEBUG - logger.py:15 - Starting execution of train_classifier
2025-04-28 22:17:47 - fraudDetection - INFO - training_pipeline.py:27 - Starting fraud classifier training
2025-04-28 22:17:50 - fraudDetection - INFO - training_pipeline.py:35 - Loaded and processed default data
2025-04-28 22:17:50 - fraudDetection - ERROR - logger.py:25 - Failed executing train_classifier after 2.5242 seconds: load_params() takes 0 positional arguments but 1 was given
2025-04-28 22:17:50 - fraudDetection - DEBUG - logger.py:26 - Traceback (most recent call last):
  File "C:\Users\renzd\Desktop\fraud_detection_system\infrastructure\utils\logger.py", line 18, in wrapper
    result = func(*args, **kwargs)
             ^^^^^^^^^^^^^^^^^^^^^
  File "C:\Users\renzd\Desktop\fraud_detection_system\training_pipeline.py", line 41, in train_classifier
    trainer = FraudClassifierTrainer()
              ^^^^^^^^^^^^^^^^^^^^^^^^
  File "C:\Users\renzd\Desktop\fraud_detection_system\experts\fraud_classifier\train.py", line 29, in __init__
    self.params = params or load_params('fraud_classifier')
                            ^^^^^^^^^^^^^^^^^^^^^^^^^^^^^^^
TypeError: load_params() takes 0 positional arguments but 1 was given

2025-04-28 22:58:05 - fraudDetection - INFO - main.py:158 - Model evaluation for both not implemented yet
2025-04-28 23:19:30 - fraudDetection - INFO - main.py:92 - Starting training pipeline
2025-04-28 23:19:30 - fraudDetection - DEBUG - logger.py:15 - Starting execution of train_classifier
2025-04-28 23:19:30 - fraudDetection - INFO - training_pipeline.py:27 - Starting fraud classifier training
2025-04-28 23:19:31 - fraudDetection - ERROR - logger.py:25 - Failed executing train_classifier after 1.1068 seconds: Unable to find a usable engine; tried using: 'pyarrow', 'fastparquet'.
A suitable version of pyarrow or fastparquet is required for parquet support.
Trying to import the above resulted in these errors:
 - Missing optional dependency 'pyarrow'. pyarrow is required for parquet support. Use pip or conda to install pyarrow.
 - Missing optional dependency 'fastparquet'. fastparquet is required for parquet support. Use pip or conda to install fastparquet.
2025-04-28 23:19:31 - fraudDetection - DEBUG - logger.py:26 - Traceback (most recent call last):
  File "C:\Users\JV\fraud_detection_system\infrastructure\utils\logger.py", line 18, in wrapper
    result = func(*args, **kwargs)
             ^^^^^^^^^^^^^^^^^^^^^
  File "C:\Users\JV\fraud_detection_system\pipelines\training_pipeline.py", line 34, in train_classifier
    df = process_raw_data(save=True)
         ^^^^^^^^^^^^^^^^^^^^^^^^^^^
  File "C:\Users\JV\fraud_detection_system\infrastructure\utils\data_loader.py", line 46, in process_raw_data
    processed_df.to_parquet(output_path, index=False)
  File "C:\Users\JV\AppData\Local\Programs\Python\Python312\Lib\site-packages\pandas\util\_decorators.py", line 333, in wrapper
    return func(*args, **kwargs)
           ^^^^^^^^^^^^^^^^^^^^^
  File "C:\Users\JV\AppData\Local\Programs\Python\Python312\Lib\site-packages\pandas\core\frame.py", line 3113, in to_parquet
    return to_parquet(
           ^^^^^^^^^^^
  File "C:\Users\JV\AppData\Local\Programs\Python\Python312\Lib\site-packages\pandas\io\parquet.py", line 476, in to_parquet
    impl = get_engine(engine)
           ^^^^^^^^^^^^^^^^^^
  File "C:\Users\JV\AppData\Local\Programs\Python\Python312\Lib\site-packages\pandas\io\parquet.py", line 67, in get_engine
    raise ImportError(
ImportError: Unable to find a usable engine; tried using: 'pyarrow', 'fastparquet'.
A suitable version of pyarrow or fastparquet is required for parquet support.
Trying to import the above resulted in these errors:
 - Missing optional dependency 'pyarrow'. pyarrow is required for parquet support. Use pip or conda to install pyarrow.
 - Missing optional dependency 'fastparquet'. fastparquet is required for parquet support. Use pip or conda to install fastparquet.

2025-04-28 23:20:18 - fraudDetection - INFO - main.py:92 - Starting training pipeline
2025-04-28 23:20:18 - fraudDetection - DEBUG - logger.py:15 - Starting execution of train_classifier
2025-04-28 23:20:18 - fraudDetection - INFO - training_pipeline.py:27 - Starting fraud classifier training
2025-04-28 23:20:20 - fraudDetection - INFO - training_pipeline.py:35 - Loaded and processed default data
2025-04-28 23:20:20 - fraudDetection - ERROR - logger.py:25 - Failed executing train_classifier after 2.2820 seconds: load_params() takes 0 positional arguments but 1 was given
2025-04-28 23:20:20 - fraudDetection - DEBUG - logger.py:26 - Traceback (most recent call last):
  File "C:\Users\JV\fraud_detection_system\infrastructure\utils\logger.py", line 18, in wrapper
    result = func(*args, **kwargs)
             ^^^^^^^^^^^^^^^^^^^^^
  File "C:\Users\JV\fraud_detection_system\pipelines\training_pipeline.py", line 41, in train_classifier
    trainer = FraudClassifierTrainer()
              ^^^^^^^^^^^^^^^^^^^^^^^^
  File "C:\Users\JV\fraud_detection_system\experts\fraud_classifier\train.py", line 29, in __init__
    self.params = params or load_params('fraud_classifier')
                            ^^^^^^^^^^^^^^^^^^^^^^^^^^^^^^^
TypeError: load_params() takes 0 positional arguments but 1 was given

2025-04-28 23:21:31 - fraudDetection - INFO - main.py:92 - Starting training pipeline
2025-04-28 23:21:31 - fraudDetection - DEBUG - logger.py:15 - Starting execution of train_classifier
2025-04-28 23:21:31 - fraudDetection - INFO - training_pipeline.py:27 - Starting fraud classifier training
2025-04-28 23:21:34 - fraudDetection - INFO - training_pipeline.py:35 - Loaded and processed default data
2025-04-28 23:21:34 - fraudDetection - INFO - train.py:31 - Initialized fraud classifier trainer with params: {'model_type': 'LogisticRegression', 'params': {'class_weight': 'balanced', 'C': 0.1, 'max_iter': 1000, 'solver': 'liblinear'}, 'rules': {'max_hourly_transactions': 5, 'amount_deviation_multiplier': 3, 'max_daily_amount': 10000, 'suspicious_countries': ['XX', 'YY', 'ZZ']}}
2025-04-28 23:21:34 - fraudDetection - ERROR - logger.py:25 - Failed executing train_classifier after 3.5300 seconds: Unsupported model type: LogisticRegression
2025-04-28 23:21:34 - fraudDetection - DEBUG - logger.py:26 - Traceback (most recent call last):
  File "C:\Users\JV\fraud_detection_system\infrastructure\utils\logger.py", line 18, in wrapper
    result = func(*args, **kwargs)
             ^^^^^^^^^^^^^^^^^^^^^
  File "C:\Users\JV\fraud_detection_system\pipelines\training_pipeline.py", line 41, in train_classifier
    trainer = FraudClassifierTrainer()
              ^^^^^^^^^^^^^^^^^^^^^^^^
  File "C:\Users\JV\fraud_detection_system\experts\fraud_classifier\train.py", line 43, in __init__
    self._init_model()
  File "C:\Users\JV\fraud_detection_system\experts\fraud_classifier\train.py", line 59, in _init_model
    raise ValueError(f"Unsupported model type: {model_type}")
ValueError: Unsupported model type: LogisticRegression

2025-04-28 23:22:31 - fraudDetection - INFO - main.py:92 - Starting training pipeline
2025-04-28 23:22:31 - fraudDetection - DEBUG - logger.py:15 - Starting execution of train_classifier
2025-04-28 23:22:31 - fraudDetection - INFO - training_pipeline.py:27 - Starting fraud classifier training
2025-04-28 23:22:33 - fraudDetection - INFO - training_pipeline.py:35 - Loaded and processed default data
2025-04-28 23:22:33 - fraudDetection - INFO - train.py:31 - Initialized fraud classifier trainer with params: {'model_type': 'LogisticRegression', 'params': {'class_weight': 'balanced', 'C': 0.1, 'max_iter': 1000, 'solver': 'liblinear'}, 'rules': {'max_hourly_transactions': 5, 'amount_deviation_multiplier': 3, 'max_daily_amount': 10000, 'suspicious_countries': ['XX', 'YY', 'ZZ']}}
2025-04-28 23:22:33 - fraudDetection - DEBUG - logger.py:15 - Starting execution of train
2025-04-28 23:22:33 - fraudDetection - INFO - train.py:110 - Training fraud classifier on 227845 samples (394 fraud instances)
2025-04-28 23:22:33 - fraudDetection - DEBUG - logger.py:15 - Starting execution of preprocess
2025-04-28 23:22:34 - fraudDetection - DEBUG - logger.py:20 - Executed preprocess in 0.8973 seconds
2025-04-28 23:22:37 - fraudDetection - INFO - train.py:162 - Top 10 important features:
2025-04-28 23:22:37 - fraudDetection - INFO - train.py:164 -   V10: -1.7450
2025-04-28 23:22:37 - fraudDetection - INFO - train.py:164 -   V4: 1.5977
2025-04-28 23:22:37 - fraudDetection - INFO - train.py:164 -   V1: 1.5443
2025-04-28 23:22:37 - fraudDetection - INFO - train.py:164 -   V14: -1.5031
2025-04-28 23:22:37 - fraudDetection - INFO - train.py:164 -   V5: 1.0812
2025-04-28 23:22:37 - fraudDetection - INFO - train.py:164 -   V17: -1.0335
2025-04-28 23:22:37 - fraudDetection - INFO - train.py:164 -   V12: -1.0129
2025-04-28 23:22:37 - fraudDetection - INFO - train.py:164 -   V16: -0.9293
2025-04-28 23:22:37 - fraudDetection - INFO - train.py:164 -   V20: -0.8766
2025-04-28 23:22:37 - fraudDetection - INFO - train.py:164 -   norm_amount: 0.8528
2025-04-28 23:22:37 - fraudDetection - DEBUG - logger.py:20 - Executed train in 3.8377 seconds
2025-04-28 23:22:37 - fraudDetection - INFO - training_pipeline.py:57 - Classifier metrics - Precision: 0.0385, Recall: 0.0102, F1: 0.0161
2025-04-28 23:22:37 - fraudDetection - DEBUG - logger.py:15 - Starting execution of save_model
2025-04-28 23:22:37 - fraudDetection - INFO - model_ops.py:35 - Saved classifier model to experts/fraud_classifier/models/classifier_model.pkl
2025-04-28 23:22:37 - fraudDetection - DEBUG - logger.py:20 - Executed save_model in 0.0064 seconds
2025-04-28 23:22:37 - fraudDetection - INFO - model_ops.py:127 - Saved fraud_classifier metrics to C:\Users\JV\fraud_detection_system\experts/fraud_classifier/evaluation\fraud_classifier_metrics.json
2025-04-28 23:22:37 - fraudDetection - DEBUG - logger.py:20 - Executed train_classifier in 5.6968 seconds
2025-04-28 23:22:37 - fraudDetection - INFO - main.py:100 - Fraud classifier training completed
2025-04-28 23:22:37 - fraudDetection - DEBUG - logger.py:15 - Starting execution of train_anomaly_detector
2025-04-28 23:22:37 - fraudDetection - INFO - training_pipeline.py:69 - Starting anomaly detector training
2025-04-28 23:22:40 - fraudDetection - INFO - training_pipeline.py:77 - Loaded and processed default data
2025-04-28 23:22:40 - fraudDetection - INFO - train.py:37 - Initialized anomaly detector trainer with contamination: 0.01
2025-04-28 23:22:40 - fraudDetection - DEBUG - logger.py:15 - Starting execution of train
2025-04-28 23:22:40 - fraudDetection - INFO - train.py:126 - Training IsolationForest anomaly detector on 284315 samples
2025-04-28 23:22:40 - fraudDetection - DEBUG - logger.py:15 - Starting execution of preprocess
2025-04-28 23:22:40 - fraudDetection - DEBUG - logger.py:20 - Executed preprocess in 0.4802 seconds
2025-04-28 23:22:42 - fraudDetection - DEBUG - logger.py:20 - Executed train in 2.1465 seconds
2025-04-28 23:22:42 - fraudDetection - DEBUG - logger.py:15 - Starting execution of preprocess
2025-04-28 23:22:43 - fraudDetection - DEBUG - logger.py:20 - Executed preprocess in 0.4836 seconds
2025-04-28 23:22:44 - fraudDetection - INFO - training_pipeline.py:109 - Anomaly detector metrics - Precision: 0.0761, Recall: 0.4736, F1: 0.1311
2025-04-28 23:22:44 - fraudDetection - DEBUG - logger.py:15 - Starting execution of save_model
2025-04-28 23:22:44 - fraudDetection - INFO - model_ops.py:35 - Saved anomaly model to experts/anomaly_detector/models/isolation_forest.pkl
2025-04-28 23:22:44 - fraudDetection - DEBUG - logger.py:20 - Executed save_model in 0.1759 seconds
2025-04-28 23:22:44 - fraudDetection - INFO - model_ops.py:127 - Saved anomaly_detector metrics to C:\Users\JV\fraud_detection_system\experts/anomaly_detector/evaluation\anomaly_detector_metrics.json
2025-04-28 23:22:44 - fraudDetection - DEBUG - logger.py:20 - Executed train_anomaly_detector in 7.4590 seconds
2025-04-28 23:22:44 - fraudDetection - INFO - main.py:105 - Anomaly detector training completed
2025-04-28 23:22:44 - fraudDetection - INFO - main.py:111 - Training pipeline completed successfully
2025-04-29 00:46:47 - fraudDetection - INFO - dynamic_adjustments.py:34 - Initialized threshold adjuster with base thresholds: {'critical': -0.7, 'high': -0.4, 'medium': -0.2, 'low': 0.0}
2025-04-29 00:47:14 - fraudDetection - ERROR - main.py:388 - No profiles command specified
2025-04-29 00:52:41 - fraudDetection - INFO - context_manager.py:148 - Listed 0 user profiles
2025-04-29 00:53:03 - fraudDetection - INFO - dynamic_adjustments.py:34 - Initialized threshold adjuster with base thresholds: {'critical': -0.7, 'high': -0.4, 'medium': -0.2, 'low': 0.0}
2025-04-29 00:53:13 - fraudDetection - INFO - rule_manager.py:32 - Loaded static rules from C:\Users\JV\fraud_detection_system\experts/fraud_classifier/rules/static_rules.json
2025-04-29 00:53:13 - fraudDetection - INFO - rule_manager.py:111 - Loaded 0 dynamic rules from database
2025-04-29 00:53:44 - fraudDetection - INFO - main.py:294 - Initializing fraud detection system
2025-04-29 00:54:42 - fraudDetection - INFO - main.py:294 - Initializing fraud detection system
2025-04-29 00:54:42 - fraudDetection - INFO - main.py:385 - Created user profiles database at C:\Users\JV\fraud_detection_system\experts/coordination/shared_context/user_profiles.db
2025-04-29 00:54:42 - fraudDetection - INFO - main.py:468 - Created dynamic rules database at C:\Users\JV\fraud_detection_system\experts/fraud_classifier/rules/dynamic_rules.db
2025-04-29 00:54:42 - fraudDetection - INFO - main.py:490 - System initialization completed
2025-04-29 00:55:26 - fraudDetection - INFO - context_manager.py:148 - Listed 0 user profiles
2025-04-29 00:55:39 - fraudDetection - INFO - rule_manager.py:32 - Loaded static rules from C:\Users\JV\fraud_detection_system\experts/fraud_classifier/rules/static_rules.json
2025-04-29 00:55:39 - fraudDetection - INFO - rule_manager.py:111 - Loaded 0 dynamic rules from database
2025-04-29 00:59:04 - fraudDetection - INFO - main.py:198 - Starting training pipeline
2025-04-29 00:59:04 - fraudDetection - INFO - main.py:217 - Training pipeline completed successfully
2025-04-29 00:59:18 - fraudDetection - INFO - main.py:198 - Starting training pipeline
2025-04-29 00:59:18 - fraudDetection - DEBUG - logger.py:15 - Starting execution of update_rules
2025-04-29 00:59:18 - fraudDetection - INFO - training_pipeline.py:121 - Updating static rules
2025-04-29 00:59:18 - fraudDetection - DEBUG - model_ops.py:89 - Loaded static rules from C:\Users\JV\fraud_detection_system\experts/fraud_classifier/rules/static_rules.json
2025-04-29 00:59:18 - fraudDetection - DEBUG - model_ops.py:89 - Loaded thresholds rules from C:\Users\JV\fraud_detection_system\experts/anomaly_detector/thresholds/base_thresholds.yaml
2025-04-29 00:59:18 - fraudDetection - INFO - model_ops.py:113 - Saved static rules to C:\Users\JV\fraud_detection_system\experts/fraud_classifier/rules/static_rules.json
2025-04-29 00:59:18 - fraudDetection - INFO - model_ops.py:113 - Saved thresholds rules to C:\Users\JV\fraud_detection_system\experts/anomaly_detector/thresholds/base_thresholds.yaml
2025-04-29 00:59:18 - fraudDetection - INFO - training_pipeline.py:137 - Rules updated successfully
2025-04-29 00:59:18 - fraudDetection - DEBUG - logger.py:20 - Executed update_rules in 0.0104 seconds
2025-04-29 00:59:18 - fraudDetection - INFO - main.py:217 - Training pipeline completed successfully
2025-04-29 01:00:00 - fraudDetection - INFO - main.py:224 - Starting inference pipeline
2025-04-29 01:00:00 - fraudDetection - DEBUG - logger.py:15 - Starting execution of load_experts
2025-04-29 01:00:00 - fraudDetection - DEBUG - logger.py:15 - Starting execution of load_model
2025-04-29 01:00:00 - fraudDetection - INFO - model_ops.py:65 - Loaded classifier model from experts/fraud_classifier/models/classifier_model.pkl
2025-04-29 01:00:00 - fraudDetection - DEBUG - logger.py:20 - Executed load_model in 0.0287 seconds
2025-04-29 01:00:00 - fraudDetection - DEBUG - logger.py:15 - Starting execution of load_model
2025-04-29 01:00:00 - fraudDetection - INFO - model_ops.py:65 - Loaded anomaly model from experts/anomaly_detector/models/isolation_forest.pkl
2025-04-29 01:00:00 - fraudDetection - DEBUG - logger.py:20 - Executed load_model in 0.0183 seconds
2025-04-29 01:00:00 - fraudDetection - INFO - context_buffer.py:47 - Context buffer initialized
2025-04-29 01:00:00 - fraudDetection - INFO - knowledge_graph.py:56 - Initialized empty knowledge graph
2025-04-29 01:00:00 - fraudDetection - INFO - knowledge_graph.py:25 - Knowledge graph initialized
2025-04-29 01:00:00 - fraudDetection - ERROR - inference_pipeline.py:49 - Error loading expert systems: expected str, bytes or os.PathLike object, not ContextBuffer
2025-04-29 01:00:00 - fraudDetection - ERROR - logger.py:25 - Failed executing load_experts after 0.0756 seconds: expected str, bytes or os.PathLike object, not ContextBuffer
2025-04-29 01:00:00 - fraudDetection - DEBUG - logger.py:26 - Traceback (most recent call last):
  File "C:\Users\JV\fraud_detection_system\infrastructure\utils\logger.py", line 18, in wrapper
    result = func(*args, **kwargs)
             ^^^^^^^^^^^^^^^^^^^^^
  File "C:\Users\JV\fraud_detection_system\pipelines\inference_pipeline.py", line 39, in load_experts
    classifier = FraudClassifierExpert(classifier_model, context)
                 ^^^^^^^^^^^^^^^^^^^^^^^^^^^^^^^^^^^^^^^^^^^^^^^^
  File "C:\Users\JV\fraud_detection_system\experts\fraud_classifier\predict.py", line 8, in __init__
    with open(rules_path) as f:
         ^^^^^^^^^^^^^^^^
TypeError: expected str, bytes or os.PathLike object, not ContextBuffer

2025-04-29 01:00:00 - fraudDetection - ERROR - main.py:230 - Failed to initialize expert systems: expected str, bytes or os.PathLike object, not ContextBuffer
2025-04-29 01:01:03 - fraudDetection - INFO - main.py:224 - Starting inference pipeline
2025-04-29 01:01:03 - fraudDetection - DEBUG - logger.py:15 - Starting execution of load_experts
2025-04-29 01:01:03 - fraudDetection - DEBUG - logger.py:15 - Starting execution of load_model
2025-04-29 01:01:03 - fraudDetection - INFO - model_ops.py:65 - Loaded classifier model from experts/fraud_classifier/models/classifier_model.pkl
2025-04-29 01:01:03 - fraudDetection - DEBUG - logger.py:20 - Executed load_model in 0.0020 seconds
2025-04-29 01:01:03 - fraudDetection - DEBUG - logger.py:15 - Starting execution of load_model
2025-04-29 01:01:03 - fraudDetection - INFO - model_ops.py:65 - Loaded anomaly model from experts/anomaly_detector/models/isolation_forest.pkl
2025-04-29 01:01:03 - fraudDetection - DEBUG - logger.py:20 - Executed load_model in 0.0035 seconds
2025-04-29 01:01:03 - fraudDetection - INFO - context_buffer.py:47 - Context buffer initialized
2025-04-29 01:01:03 - fraudDetection - INFO - knowledge_graph.py:56 - Initialized empty knowledge graph
2025-04-29 01:01:03 - fraudDetection - INFO - knowledge_graph.py:25 - Knowledge graph initialized
2025-04-29 01:01:03 - fraudDetection - ERROR - inference_pipeline.py:49 - Error loading expert systems: expected str, bytes or os.PathLike object, not ContextBuffer
2025-04-29 01:01:03 - fraudDetection - ERROR - logger.py:25 - Failed executing load_experts after 0.0130 seconds: expected str, bytes or os.PathLike object, not ContextBuffer
2025-04-29 01:01:03 - fraudDetection - DEBUG - logger.py:26 - Traceback (most recent call last):
  File "C:\Users\JV\fraud_detection_system\infrastructure\utils\logger.py", line 18, in wrapper
    result = func(*args, **kwargs)
             ^^^^^^^^^^^^^^^^^^^^^
  File "C:\Users\JV\fraud_detection_system\pipelines\inference_pipeline.py", line 39, in load_experts
    classifier = FraudClassifierExpert(classifier_model, context)
                 ^^^^^^^^^^^^^^^^^^^^^^^^^^^^^^^^^^^^^^^^^^^^^^^^
  File "C:\Users\JV\fraud_detection_system\experts\fraud_classifier\predict.py", line 8, in __init__
    with open(rules_path) as f:
         ^^^^^^^^^^^^^^^^
TypeError: expected str, bytes or os.PathLike object, not ContextBuffer

2025-04-29 01:01:03 - fraudDetection - ERROR - main.py:230 - Failed to initialize expert systems: expected str, bytes or os.PathLike object, not ContextBuffer
2025-04-29 01:01:42 - fraudDetection - INFO - main.py:224 - Starting inference pipeline
2025-04-29 01:01:42 - fraudDetection - DEBUG - logger.py:15 - Starting execution of load_experts
2025-04-29 01:01:42 - fraudDetection - DEBUG - logger.py:15 - Starting execution of load_model
2025-04-29 01:01:42 - fraudDetection - INFO - model_ops.py:65 - Loaded classifier model from experts/fraud_classifier/models/classifier_model.pkl
2025-04-29 01:01:42 - fraudDetection - DEBUG - logger.py:20 - Executed load_model in 0.0020 seconds
2025-04-29 01:01:42 - fraudDetection - DEBUG - logger.py:15 - Starting execution of load_model
2025-04-29 01:01:42 - fraudDetection - INFO - model_ops.py:65 - Loaded anomaly model from experts/anomaly_detector/models/isolation_forest.pkl
2025-04-29 01:01:42 - fraudDetection - DEBUG - logger.py:20 - Executed load_model in 0.0030 seconds
2025-04-29 01:01:42 - fraudDetection - INFO - context_buffer.py:47 - Context buffer initialized
2025-04-29 01:01:42 - fraudDetection - INFO - knowledge_graph.py:56 - Initialized empty knowledge graph
2025-04-29 01:01:42 - fraudDetection - INFO - knowledge_graph.py:25 - Knowledge graph initialized
2025-04-29 01:01:42 - fraudDetection - ERROR - inference_pipeline.py:49 - Error loading expert systems: expected str, bytes or os.PathLike object, not ContextBuffer
2025-04-29 01:01:42 - fraudDetection - ERROR - logger.py:25 - Failed executing load_experts after 0.0117 seconds: expected str, bytes or os.PathLike object, not ContextBuffer
2025-04-29 01:01:42 - fraudDetection - DEBUG - logger.py:26 - Traceback (most recent call last):
  File "C:\Users\JV\fraud_detection_system\infrastructure\utils\logger.py", line 18, in wrapper
    result = func(*args, **kwargs)
             ^^^^^^^^^^^^^^^^^^^^^
  File "C:\Users\JV\fraud_detection_system\pipelines\inference_pipeline.py", line 39, in load_experts
    classifier = FraudClassifierExpert(classifier_model, context)
                 ^^^^^^^^^^^^^^^^^^^^^^^^^^^^^^^^^^^^^^^^^^^^^^^^
  File "C:\Users\JV\fraud_detection_system\experts\fraud_classifier\predict.py", line 8, in __init__
    with open(rules_path) as f:
         ^^^^^^^^^^^^^^^^
TypeError: expected str, bytes or os.PathLike object, not ContextBuffer

2025-04-29 01:01:42 - fraudDetection - ERROR - main.py:230 - Failed to initialize expert systems: expected str, bytes or os.PathLike object, not ContextBuffer
2025-04-29 01:03:13 - fraudDetection - INFO - main.py:224 - Starting inference pipeline
2025-04-29 01:03:13 - fraudDetection - DEBUG - logger.py:15 - Starting execution of load_experts
2025-04-29 01:03:13 - fraudDetection - DEBUG - logger.py:15 - Starting execution of load_model
2025-04-29 01:03:13 - fraudDetection - INFO - model_ops.py:65 - Loaded classifier model from experts/fraud_classifier/models/classifier_model.pkl
2025-04-29 01:03:13 - fraudDetection - DEBUG - logger.py:20 - Executed load_model in 0.0027 seconds
2025-04-29 01:03:13 - fraudDetection - DEBUG - logger.py:15 - Starting execution of load_model
2025-04-29 01:03:13 - fraudDetection - INFO - model_ops.py:65 - Loaded anomaly model from experts/anomaly_detector/models/isolation_forest.pkl
2025-04-29 01:03:13 - fraudDetection - DEBUG - logger.py:20 - Executed load_model in 0.0085 seconds
2025-04-29 01:03:13 - fraudDetection - INFO - context_buffer.py:47 - Context buffer initialized
2025-04-29 01:03:13 - fraudDetection - INFO - knowledge_graph.py:56 - Initialized empty knowledge graph
2025-04-29 01:03:13 - fraudDetection - INFO - knowledge_graph.py:25 - Knowledge graph initialized
2025-04-29 01:03:13 - fraudDetection - INFO - dynamic_adjustments.py:34 - Initialized threshold adjuster with base thresholds: {'critical': -0.7, 'high': -0.4, 'low': 0.0, 'medium': -0.2}
2025-04-29 01:03:13 - fraudDetection - INFO - detect.py:36 - Initialized anomaly detector expert with thresholds: {'critical': -0.7, 'high': -0.4, 'low': 0.0, 'medium': -0.2}
2025-04-29 01:03:13 - fraudDetection - INFO - inference_pipeline.py:49 - Expert systems loaded successfully
2025-04-29 01:03:13 - fraudDetection - DEBUG - logger.py:20 - Executed load_experts in 0.0640 seconds
2025-04-29 01:03:13 - fraudDetection - DEBUG - logger.py:15 - Starting execution of process_single_transaction
2025-04-29 01:03:13 - fraudDetection - ERROR - logger.py:25 - Failed executing process_single_transaction after 0.0050 seconds: Expected 2D array, got 1D array instead:
array=[{'id': 'test123', 'amount': 1000, 'merchant': 'Test Store', 'merchant_category': 'retail', 'country': 'US', 'hour_of_day': 14, 'user_id': 'user123'}].
Reshape your data either using array.reshape(-1, 1) if your data has a single feature or array.reshape(1, -1) if it contains a single sample.
2025-04-29 01:03:14 - fraudDetection - DEBUG - logger.py:26 - Traceback (most recent call last):
  File "C:\Users\JV\fraud_detection_system\infrastructure\utils\logger.py", line 18, in wrapper
    result = func(*args, **kwargs)
             ^^^^^^^^^^^^^^^^^^^^^
  File "C:\Users\JV\fraud_detection_system\pipelines\inference_pipeline.py", line 60, in process_single_transaction
    result = mediator.process_transaction(transaction)
             ^^^^^^^^^^^^^^^^^^^^^^^^^^^^^^^^^^^^^^^^^
  File "C:\Users\JV\fraud_detection_system\experts\coordination\mediator.py", line 35, in process_transaction
    class_report = self.classifier.evaluate(transaction)
                   ^^^^^^^^^^^^^^^^^^^^^^^^^^^^^^^^^^^^^
  File "C:\Users\JV\fraud_detection_system\experts\fraud_classifier\predict.py", line 39, in evaluate
    ml_score = self.model.predict_proba([transaction])[0][1]
               ^^^^^^^^^^^^^^^^^^^^^^^^^^^^^^^^^^^^^^^
  File "C:\Users\JV\AppData\Local\Programs\Python\Python312\Lib\site-packages\sklearn\linear_model\_logistic.py", line 1428, in predict_proba
    return super()._predict_proba_lr(X)
           ^^^^^^^^^^^^^^^^^^^^^^^^^^^^
  File "C:\Users\JV\AppData\Local\Programs\Python\Python312\Lib\site-packages\sklearn\linear_model\_base.py", line 389, in _predict_proba_lr
    prob = self.decision_function(X)
           ^^^^^^^^^^^^^^^^^^^^^^^^^
  File "C:\Users\JV\AppData\Local\Programs\Python\Python312\Lib\site-packages\sklearn\linear_model\_base.py", line 351, in decision_function
    X = validate_data(self, X, accept_sparse="csr", reset=False)
        ^^^^^^^^^^^^^^^^^^^^^^^^^^^^^^^^^^^^^^^^^^^^^^^^^^^^^^^^
  File "C:\Users\JV\AppData\Local\Programs\Python\Python312\Lib\site-packages\sklearn\utils\validation.py", line 2944, in validate_data
    out = check_array(X, input_name="X", **check_params)
          ^^^^^^^^^^^^^^^^^^^^^^^^^^^^^^^^^^^^^^^^^^^^^^
  File "C:\Users\JV\AppData\Local\Programs\Python\Python312\Lib\site-packages\sklearn\utils\validation.py", line 1093, in check_array
    raise ValueError(msg)
ValueError: Expected 2D array, got 1D array instead:
array=[{'id': 'test123', 'amount': 1000, 'merchant': 'Test Store', 'merchant_category': 'retail', 'country': 'US', 'hour_of_day': 14, 'user_id': 'user123'}].
Reshape your data either using array.reshape(-1, 1) if your data has a single feature or array.reshape(1, -1) if it contains a single sample.

2025-04-29 01:03:14 - fraudDetection - ERROR - main.py:256 - Error in inference pipeline: Expected 2D array, got 1D array instead:
array=[{'id': 'test123', 'amount': 1000, 'merchant': 'Test Store', 'merchant_category': 'retail', 'country': 'US', 'hour_of_day': 14, 'user_id': 'user123'}].
Reshape your data either using array.reshape(-1, 1) if your data has a single feature or array.reshape(1, -1) if it contains a single sample.
2025-04-29 01:03:37 - fraudDetection - INFO - main.py:224 - Starting inference pipeline
2025-04-29 01:03:37 - fraudDetection - DEBUG - logger.py:15 - Starting execution of load_experts
2025-04-29 01:03:37 - fraudDetection - DEBUG - logger.py:15 - Starting execution of load_model
2025-04-29 01:03:37 - fraudDetection - INFO - model_ops.py:65 - Loaded classifier model from experts/fraud_classifier/models/classifier_model.pkl
2025-04-29 01:03:37 - fraudDetection - DEBUG - logger.py:20 - Executed load_model in 0.0021 seconds
2025-04-29 01:03:37 - fraudDetection - DEBUG - logger.py:15 - Starting execution of load_model
2025-04-29 01:03:37 - fraudDetection - INFO - model_ops.py:65 - Loaded anomaly model from experts/anomaly_detector/models/isolation_forest.pkl
2025-04-29 01:03:37 - fraudDetection - DEBUG - logger.py:20 - Executed load_model in 0.0046 seconds
2025-04-29 01:03:37 - fraudDetection - INFO - context_buffer.py:47 - Context buffer initialized
2025-04-29 01:03:37 - fraudDetection - INFO - knowledge_graph.py:56 - Initialized empty knowledge graph
2025-04-29 01:03:37 - fraudDetection - INFO - knowledge_graph.py:25 - Knowledge graph initialized
2025-04-29 01:03:37 - fraudDetection - INFO - dynamic_adjustments.py:34 - Initialized threshold adjuster with base thresholds: {'critical': -0.7, 'high': -0.4, 'low': 0.0, 'medium': -0.2}
2025-04-29 01:03:37 - fraudDetection - INFO - detect.py:36 - Initialized anomaly detector expert with thresholds: {'critical': -0.7, 'high': -0.4, 'low': 0.0, 'medium': -0.2}
2025-04-29 01:03:37 - fraudDetection - INFO - inference_pipeline.py:49 - Expert systems loaded successfully
2025-04-29 01:03:37 - fraudDetection - DEBUG - logger.py:20 - Executed load_experts in 0.0233 seconds
2025-04-29 01:03:37 - fraudDetection - DEBUG - logger.py:15 - Starting execution of process_single_transaction
2025-04-29 01:03:37 - fraudDetection - ERROR - logger.py:25 - Failed executing process_single_transaction after 0.0011 seconds: Expected 2D array, got 1D array instead:
array=[{'id': 'test123', 'amount': 1000, 'merchant': 'Test Store', 'merchant_category': 'retail', 'country': 'US', 'hour_of_day': 14, 'user_id': 'user123'}].
Reshape your data either using array.reshape(-1, 1) if your data has a single feature or array.reshape(1, -1) if it contains a single sample.
2025-04-29 01:03:37 - fraudDetection - DEBUG - logger.py:26 - Traceback (most recent call last):
  File "C:\Users\JV\fraud_detection_system\infrastructure\utils\logger.py", line 18, in wrapper
    result = func(*args, **kwargs)
             ^^^^^^^^^^^^^^^^^^^^^
  File "C:\Users\JV\fraud_detection_system\pipelines\inference_pipeline.py", line 60, in process_single_transaction
    result = mediator.process_transaction(transaction)
             ^^^^^^^^^^^^^^^^^^^^^^^^^^^^^^^^^^^^^^^^^
  File "C:\Users\JV\fraud_detection_system\experts\coordination\mediator.py", line 35, in process_transaction
    class_report = self.classifier.evaluate(transaction)
                   ^^^^^^^^^^^^^^^^^^^^^^^^^^^^^^^^^^^^^
  File "C:\Users\JV\fraud_detection_system\experts\fraud_classifier\predict.py", line 39, in evaluate
    ml_score = self.model.predict_proba([transaction])[0][1]
               ^^^^^^^^^^^^^^^^^^^^^^^^^^^^^^^^^^^^^^^
  File "C:\Users\JV\AppData\Local\Programs\Python\Python312\Lib\site-packages\sklearn\linear_model\_logistic.py", line 1428, in predict_proba
    return super()._predict_proba_lr(X)
           ^^^^^^^^^^^^^^^^^^^^^^^^^^^^
  File "C:\Users\JV\AppData\Local\Programs\Python\Python312\Lib\site-packages\sklearn\linear_model\_base.py", line 389, in _predict_proba_lr
    prob = self.decision_function(X)
           ^^^^^^^^^^^^^^^^^^^^^^^^^
  File "C:\Users\JV\AppData\Local\Programs\Python\Python312\Lib\site-packages\sklearn\linear_model\_base.py", line 351, in decision_function
    X = validate_data(self, X, accept_sparse="csr", reset=False)
        ^^^^^^^^^^^^^^^^^^^^^^^^^^^^^^^^^^^^^^^^^^^^^^^^^^^^^^^^
  File "C:\Users\JV\AppData\Local\Programs\Python\Python312\Lib\site-packages\sklearn\utils\validation.py", line 2944, in validate_data
    out = check_array(X, input_name="X", **check_params)
          ^^^^^^^^^^^^^^^^^^^^^^^^^^^^^^^^^^^^^^^^^^^^^^
  File "C:\Users\JV\AppData\Local\Programs\Python\Python312\Lib\site-packages\sklearn\utils\validation.py", line 1093, in check_array
    raise ValueError(msg)
ValueError: Expected 2D array, got 1D array instead:
array=[{'id': 'test123', 'amount': 1000, 'merchant': 'Test Store', 'merchant_category': 'retail', 'country': 'US', 'hour_of_day': 14, 'user_id': 'user123'}].
Reshape your data either using array.reshape(-1, 1) if your data has a single feature or array.reshape(1, -1) if it contains a single sample.

2025-04-29 01:03:37 - fraudDetection - ERROR - main.py:256 - Error in inference pipeline: Expected 2D array, got 1D array instead:
array=[{'id': 'test123', 'amount': 1000, 'merchant': 'Test Store', 'merchant_category': 'retail', 'country': 'US', 'hour_of_day': 14, 'user_id': 'user123'}].
Reshape your data either using array.reshape(-1, 1) if your data has a single feature or array.reshape(1, -1) if it contains a single sample.
2025-04-29 01:04:46 - fraudDetection - INFO - main.py:224 - Starting inference pipeline
2025-04-29 01:04:46 - fraudDetection - DEBUG - logger.py:15 - Starting execution of load_experts
2025-04-29 01:04:46 - fraudDetection - DEBUG - logger.py:15 - Starting execution of load_model
2025-04-29 01:04:46 - fraudDetection - INFO - model_ops.py:65 - Loaded classifier model from experts/fraud_classifier/models/classifier_model.pkl
2025-04-29 01:04:46 - fraudDetection - DEBUG - logger.py:20 - Executed load_model in 0.0010 seconds
2025-04-29 01:04:46 - fraudDetection - DEBUG - logger.py:15 - Starting execution of load_model
2025-04-29 01:04:46 - fraudDetection - INFO - model_ops.py:65 - Loaded anomaly model from experts/anomaly_detector/models/isolation_forest.pkl
2025-04-29 01:04:46 - fraudDetection - DEBUG - logger.py:20 - Executed load_model in 0.0063 seconds
2025-04-29 01:04:46 - fraudDetection - INFO - context_buffer.py:47 - Context buffer initialized
2025-04-29 01:04:46 - fraudDetection - INFO - knowledge_graph.py:56 - Initialized empty knowledge graph
2025-04-29 01:04:46 - fraudDetection - INFO - knowledge_graph.py:25 - Knowledge graph initialized
2025-04-29 01:04:46 - fraudDetection - INFO - dynamic_adjustments.py:34 - Initialized threshold adjuster with base thresholds: {'critical': -0.7, 'high': -0.4, 'low': 0.0, 'medium': -0.2}
2025-04-29 01:04:46 - fraudDetection - INFO - detect.py:36 - Initialized anomaly detector expert with thresholds: {'critical': -0.7, 'high': -0.4, 'low': 0.0, 'medium': -0.2}
2025-04-29 01:04:46 - fraudDetection - INFO - inference_pipeline.py:49 - Expert systems loaded successfully
2025-04-29 01:04:46 - fraudDetection - DEBUG - logger.py:20 - Executed load_experts in 0.0166 seconds
2025-04-29 01:04:46 - fraudDetection - DEBUG - logger.py:15 - Starting execution of process_single_transaction
2025-04-29 01:04:46 - fraudDetection - ERROR - logger.py:25 - Failed executing process_single_transaction after 0.0050 seconds: float() argument must be a string or a real number, not 'dict'
2025-04-29 01:04:46 - fraudDetection - DEBUG - logger.py:26 - Traceback (most recent call last):
  File "C:\Users\JV\fraud_detection_system\infrastructure\utils\logger.py", line 18, in wrapper
    result = func(*args, **kwargs)
             ^^^^^^^^^^^^^^^^^^^^^
  File "C:\Users\JV\fraud_detection_system\pipelines\inference_pipeline.py", line 60, in process_single_transaction
    result = mediator.process_transaction(transaction)
             ^^^^^^^^^^^^^^^^^^^^^^^^^^^^^^^^^^^^^^^^^
  File "C:\Users\JV\fraud_detection_system\experts\coordination\mediator.py", line 36, in process_transaction
    anom_report = self.detector.analyze(transaction)
                  ^^^^^^^^^^^^^^^^^^^^^^^^^^^^^^^^^^
  File "C:\Users\JV\fraud_detection_system\experts\anomaly_detector\detect.py", line 70, in analyze
    raw_score = self.model.decision_function([transaction])[0]
                ^^^^^^^^^^^^^^^^^^^^^^^^^^^^^^^^^^^^^^^^^^^
  File "C:\Users\JV\AppData\Local\Programs\Python\Python312\Lib\site-packages\sklearn\ensemble\_iforest.py", line 474, in decision_function
    return self.score_samples(X) - self.offset_
           ^^^^^^^^^^^^^^^^^^^^^
  File "C:\Users\JV\AppData\Local\Programs\Python\Python312\Lib\site-packages\sklearn\ensemble\_iforest.py", line 519, in score_samples
    X = validate_data(
        ^^^^^^^^^^^^^^
  File "C:\Users\JV\AppData\Local\Programs\Python\Python312\Lib\site-packages\sklearn\utils\validation.py", line 2944, in validate_data
    out = check_array(X, input_name="X", **check_params)
          ^^^^^^^^^^^^^^^^^^^^^^^^^^^^^^^^^^^^^^^^^^^^^^
  File "C:\Users\JV\AppData\Local\Programs\Python\Python312\Lib\site-packages\sklearn\utils\validation.py", line 1055, in check_array
    array = _asarray_with_order(array, order=order, dtype=dtype, xp=xp)
            ^^^^^^^^^^^^^^^^^^^^^^^^^^^^^^^^^^^^^^^^^^^^^^^^^^^^^^^^^^^
  File "C:\Users\JV\AppData\Local\Programs\Python\Python312\Lib\site-packages\sklearn\utils\_array_api.py", line 839, in _asarray_with_order
    array = numpy.asarray(array, order=order, dtype=dtype)
            ^^^^^^^^^^^^^^^^^^^^^^^^^^^^^^^^^^^^^^^^^^^^^^
TypeError: float() argument must be a string or a real number, not 'dict'

2025-04-29 01:04:46 - fraudDetection - ERROR - main.py:256 - Error in inference pipeline: float() argument must be a string or a real number, not 'dict'
2025-04-29 01:05:45 - fraudDetection - INFO - main.py:224 - Starting inference pipeline
2025-04-29 01:05:45 - fraudDetection - DEBUG - logger.py:15 - Starting execution of load_experts
2025-04-29 01:05:45 - fraudDetection - DEBUG - logger.py:15 - Starting execution of load_model
2025-04-29 01:05:45 - fraudDetection - INFO - model_ops.py:65 - Loaded classifier model from experts/fraud_classifier/models/classifier_model.pkl
2025-04-29 01:05:45 - fraudDetection - DEBUG - logger.py:20 - Executed load_model in 0.0025 seconds
2025-04-29 01:05:45 - fraudDetection - DEBUG - logger.py:15 - Starting execution of load_model
2025-04-29 01:05:45 - fraudDetection - INFO - model_ops.py:65 - Loaded anomaly model from experts/anomaly_detector/models/isolation_forest.pkl
2025-04-29 01:05:45 - fraudDetection - DEBUG - logger.py:20 - Executed load_model in 0.0049 seconds
2025-04-29 01:05:45 - fraudDetection - INFO - context_buffer.py:47 - Context buffer initialized
2025-04-29 01:05:45 - fraudDetection - INFO - knowledge_graph.py:56 - Initialized empty knowledge graph
2025-04-29 01:05:45 - fraudDetection - INFO - knowledge_graph.py:25 - Knowledge graph initialized
2025-04-29 01:05:45 - fraudDetection - INFO - dynamic_adjustments.py:34 - Initialized threshold adjuster with base thresholds: {'critical': -0.7, 'high': -0.4, 'low': 0.0, 'medium': -0.2}
2025-04-29 01:05:45 - fraudDetection - INFO - detect.py:36 - Initialized anomaly detector expert with thresholds: {'critical': -0.7, 'high': -0.4, 'low': 0.0, 'medium': -0.2}
2025-04-29 01:05:45 - fraudDetection - INFO - inference_pipeline.py:49 - Expert systems loaded successfully
2025-04-29 01:05:45 - fraudDetection - DEBUG - logger.py:20 - Executed load_experts in 0.0233 seconds
2025-04-29 01:05:45 - fraudDetection - DEBUG - logger.py:15 - Starting execution of process_single_transaction
2025-04-29 01:05:45 - fraudDetection - ERROR - logger.py:25 - Failed executing process_single_transaction after 0.0100 seconds: 'NoneType' object has no attribute 'update'
2025-04-29 01:05:45 - fraudDetection - DEBUG - logger.py:26 - Traceback (most recent call last):
  File "C:\Users\JV\fraud_detection_system\infrastructure\utils\logger.py", line 18, in wrapper
    result = func(*args, **kwargs)
             ^^^^^^^^^^^^^^^^^^^^^
  File "C:\Users\JV\fraud_detection_system\pipelines\inference_pipeline.py", line 60, in process_single_transaction
    result = mediator.process_transaction(transaction)
             ^^^^^^^^^^^^^^^^^^^^^^^^^^^^^^^^^^^^^^^^^
  File "C:\Users\JV\fraud_detection_system\experts\coordination\mediator.py", line 39, in process_transaction
    self.context.update(transaction, class_report, anom_report)
    ^^^^^^^^^^^^^^^^^^^
AttributeError: 'NoneType' object has no attribute 'update'

2025-04-29 01:05:45 - fraudDetection - ERROR - main.py:256 - Error in inference pipeline: 'NoneType' object has no attribute 'update'
2025-04-29 01:06:41 - fraudDetection - INFO - main.py:224 - Starting inference pipeline
2025-04-29 01:06:41 - fraudDetection - DEBUG - logger.py:15 - Starting execution of load_experts
2025-04-29 01:06:41 - fraudDetection - DEBUG - logger.py:15 - Starting execution of load_model
2025-04-29 01:06:41 - fraudDetection - INFO - model_ops.py:65 - Loaded classifier model from experts/fraud_classifier/models/classifier_model.pkl
2025-04-29 01:06:41 - fraudDetection - DEBUG - logger.py:20 - Executed load_model in 0.0010 seconds
2025-04-29 01:06:41 - fraudDetection - DEBUG - logger.py:15 - Starting execution of load_model
2025-04-29 01:06:41 - fraudDetection - INFO - model_ops.py:65 - Loaded anomaly model from experts/anomaly_detector/models/isolation_forest.pkl
2025-04-29 01:06:41 - fraudDetection - DEBUG - logger.py:20 - Executed load_model in 0.0036 seconds
2025-04-29 01:06:41 - fraudDetection - INFO - context_buffer.py:47 - Context buffer initialized
2025-04-29 01:06:41 - fraudDetection - INFO - knowledge_graph.py:56 - Initialized empty knowledge graph
2025-04-29 01:06:41 - fraudDetection - INFO - knowledge_graph.py:25 - Knowledge graph initialized
2025-04-29 01:06:41 - fraudDetection - INFO - dynamic_adjustments.py:34 - Initialized threshold adjuster with base thresholds: {'critical': -0.7, 'high': -0.4, 'low': 0.0, 'medium': -0.2}
2025-04-29 01:06:41 - fraudDetection - INFO - detect.py:36 - Initialized anomaly detector expert with thresholds: {'critical': -0.7, 'high': -0.4, 'low': 0.0, 'medium': -0.2}
2025-04-29 01:06:41 - fraudDetection - INFO - context_buffer.py:47 - Context buffer initialized
2025-04-29 01:06:41 - fraudDetection - INFO - inference_pipeline.py:49 - Expert systems loaded successfully
2025-04-29 01:06:41 - fraudDetection - DEBUG - logger.py:20 - Executed load_experts in 0.0276 seconds
2025-04-29 01:06:41 - fraudDetection - DEBUG - logger.py:15 - Starting execution of process_single_transaction
2025-04-29 01:06:41 - fraudDetection - INFO - mediator.py:50 - Experts collab decision: ALLOW
2025-04-29 01:06:41 - fraudDetection - INFO - inference_pipeline.py:65 - Transaction test123 processed with decision: ALLOW
2025-04-29 01:06:41 - fraudDetection - DEBUG - logger.py:20 - Executed process_single_transaction in 0.0102 seconds
2025-04-29 01:06:41 - fraudDetection - INFO - main.py:259 - Inference pipeline completed successfully
2025-04-29 01:09:37 - fraudDetection - INFO - main.py:264 - Model evaluation for both not implemented yet
